Workbook

Sheet Sheet4
B2: 🎓 Cek Status Beasiswa Citra 2026
B4: Masukkan NIM Anda
B5: 25M-A11-0003
B8: 👤 Data Mahasiswa
B9: Nama | C9: =IF( Sheet4!B5="", "", IFERROR( _xlfn.XLOOKUP(Sheet4!B5,datasts[NIM],datasts[Nama]), "Maaf NIM Tidak Ditemukan" )) -> Citra Nugroho
B10: Angkatan | C10: =IF( Sheet4!B5="", "", IFERROR( _xlfn.XLOOKUP(Sheet4!B5,datasts[NIM],datasts[Angkatan]), "Maaf NIM Tidak Ditemukan" )) -> 2025
B11: Status | C11: =IF( Sheet4!B5="", "", IFERROR( _xlfn.XLOOKUP(Sheet4!B5,datasts[NIM],datasts[[Status ]]), "Maaf NIM Tidak Ditemukan" )) -> Tidak Eligible
B13: =IF(B5="","", IFERROR( IF(C11="Eligible", "Selamat! Anda memenuhi syarat untuk mendaftar Beasiswa Citra 2026", "Maaf, Anda belum memenuhi persyaratan Beasiswa Citra 2026"), "Maaf, NIM tidak ditemukan.")) -> Maaf, Anda belum memenuhi persyaratan Beasiswa Citra 2026

Sheet Data Status Pendaftar
A1: No | B1: NIM | C1: Nama | D1: Jenis Kelamin | E1: Angkatan | F1: Fakultas | G1: Jurusan | H1: Semester | I1: IPK | J1: Nilai Terendah | K1: Status
A2: 1 | B2: 25M-A11-0001 | C2: Zaki Oktavianus | D2: L | E2: =LEFT(B2,2)+2000 -> 2025 | F2: =INDEX('Data Mahasiswa'!$N$1:$Q$14, MATCH(MID('Data Status Pendaftar'!B2, 5,2), 'Data Mahasiswa'!$N$1:$N$14,0),2) -> Sains | G2: {=INDEX('Data Mahasiswa'!$Q$2:$Q$14, MATCH(MID('Data Status Pendaftar'!B2,5,3), 'Data Mahasiswa'!$N$2:$N$14&TEXT('Data Mahasiswa'!$P$2:$P$14,"0"), 0))} -> Matematika | H2: =(YEAR(TODAY())-E2)*2 -> 2 | I2: =INDEX('Data Mahasiswa'!$A$1:$J$701, MATCH('Data Status Pendaftar'!B2, 'Data Mahasiswa'!$A$1:$A$701, 0), 10) -> 3.4791667 | J2: {=INDEX('Data Mahasiswa'!B2:I2,MATCH(MIN(VLOOKUP('Data Mahasiswa'!B2:I2,'Data Mahasiswa'!$N$27:$O$36,2,0)),VLOOKUP('Data Mahasiswa'!B2:I2,'Data Mahasiswa'!$N$27:$O$36,2,0),0))} -> B- | K2: =IF(AND(E2=2025,I2>=2.75,OR(J2="A",J2="A-",J2="B+",J2="B",J2="B-",J2="C+",J2="C",J2="C-")),"Eligible","Tidak Eligible") -> Eligible
A3: 2 | B3: 25M-A11-0002 | C3: Rina Kusuma | D3: P | E3: =LEFT(B3,2)+2000 -> 2025 | F3: =INDEX('Data Mahasiswa'!$N$1:$Q$14, MATCH(MID('Data Status Pendaftar'!B3, 5,2), 'Data Mahasiswa'!$N$1:$N$14,0),2) -> Sains | G3: {=INDEX('Data Mahasiswa'!$Q$2:$Q$14, MATCH(MID('Data Status Pendaftar'!B3,5,3), 'Data Mahasiswa'!$N$2:$N$14&TEXT('Data Mahasiswa'!$P$2:$P$14,"0"), 0))} -> Matematika | H3: =(YEAR(TODAY())-E3)*2 -> 2 | I3: =INDEX('Data Mahasiswa'!$A$1:$J$701, MATCH('Data Status Pendaftar'!B3, 'Data Mahasiswa'!$A$1:$A$701, 0), 10) -> 3.7083333 | J3: {=INDEX('Data Mahasiswa'!B3:I3,MATCH(MIN(VLOOKUP('Data Mahasiswa'!B3:I3,'Data Mahasiswa'!$N$27:$O$36,2,0)),VLOOKUP('Data Mahasiswa'!B3:I3,'Data Mahasiswa'!$N$27:$O$36,2,0),0))} -> C+ | K3: =IF(AND(E3=2025,I3>=2.75,OR(J3="A",J3="A-",J3="B+",J3="B",J3="B-",J3="C+",J3="C",J3="C-")),"Eligible","Tidak Eligible") -> Eligible
A4: 3 | B4: 25M-A11-0003 | C4: Citra Nugroho | D4: P | E4: =LEFT(B4,2)+2000 -> 2025 | F4: =INDEX('Data Mahasiswa'!$N$1:$Q$14, MATCH(MID('Data Status Pendaftar'!B4, 5,2), 'Data Mahasiswa'!$N$1:$N$14,0),2) -> Sains | G4: {=INDEX('Data Mahasiswa'!$Q$2:$Q$14, MATCH(MID('Data Status Pendaftar'!B4,5,3), 'Data Mahasiswa'!$N$2:$N$14&TEXT('Data Mahasiswa'!$P$2:$P$14,"0"), 0))} -> Matematika | H4: =(YEAR(TODAY())-E4)*2 -> 2 | I4: =INDEX('Data Mahasiswa'!$A$1:$J$701, MATCH('Data Status Pendaftar'!B4, 'Data Mahasiswa'!$A$1:$A$701, 0), 10) -> 2.5625 | J4: {=INDEX('Data Mahasiswa'!B4:I4,MATCH(MIN(VLOOKUP('Data Mahasiswa'!B4:I4,'Data Mahasiswa'!$N$27:$O$36,2,0)),VLOOKUP('Data Mahasiswa'!B4:I4,'Data Mahasiswa'!$N$27:$O$36,2,0),0))} -> E | K4: =IF(AND(E4=2025,I4>=2.75,OR(J4="A",J4="A-",J4="B+",J4="B",J4="B-",J4="C+",J4="C",J4="C-")),"Eligible","Tidak Eligible") -> Tidak Eligible
A5: 4 | B5: 25M-A11-0004 | C5: Oki Wijaya | D5: L | E5: =LEFT(B5,2)+2000 -> 2025 | F5: =INDEX('Data Mahasiswa'!$N$1:$Q$14, MATCH(MID('Data Status Pendaftar'!B5, 5,2), 'Data Mahasiswa'!$N$1:$N$14,0),2) -> Sains | G5: {=INDEX('Data Mahasiswa'!$Q$2:$Q$14, MATCH(MID('Data Status Pendaftar'!B5,5,3), 'Data Mahasiswa'!$N$2:$N$14&TEXT('Data Mahasiswa'!$P$2:$P$14,"0"), 0))} -> Matematika | H5: =(YEAR(TODAY())-E5)*2 -> 2 | I5: =INDEX('Data Mahasiswa'!$A$1:$J$701, MATCH('Data Status Pendaftar'!B5, 'Data Mahasiswa'!$A$1:$A$701, 0), 10) -> 3.4270833 | J5: {=INDEX('Data Mahasiswa'!B5:I5,MATCH(MIN(VLOOKUP('Data Mahasiswa'!B5:I5,'Data Mahasiswa'!$N$27:$O$36,2,0)),VLOOKUP('Data Mahasiswa'!B5:I5,'Data Mahasiswa'!$N$27:$O$36,2,0),0))} -> C+ | K5: =IF(AND(E5=2025,I5>=2.75,OR(J5="A",J5="A-",J5="B+",J5="B",J5="B-",J5="C+",J5="C",J5="C-")),"Eligible","Tidak Eligible") -> Eligible
A6: 5 | B6: 25M-A11-0005 | C6: Eka Hidayat | D6: P | E6: =LEFT(B6,2)+2000 -> 2025 | F6: =INDEX('Data Mahasiswa'!$N$1:$Q$14, MATCH(MID('Data Status Pendaftar'!B6, 5,2), 'Data Mahasiswa'!$N$1:$N$14,0),2) -> Sains | G6: {=INDEX('Data Mahasiswa'!$Q$2:$Q$14, MATCH(MID('Data Status Pendaftar'!B6,5,3), 'Data Mahasiswa'!$N$2:$N$14&TEXT('Data Mahasiswa'!$P$2:$P$14,"0"), 0))} -> Matematika | H6: =(YEAR(TODAY())-E6)*2 -> 2 | I6: =INDEX('Data Mahasiswa'!$A$1:$J$701, MATCH('Data Status Pendaftar'!B6, 'Data Mahasiswa'!$A$1:$A$701, 0), 10) -> 3.4270833 | J6: {=INDEX('Data Mahasiswa'!B6:I6,MATCH(MIN(VLOOKUP('Data Mahasiswa'!B6:I6,'Data Mahasiswa'!$N$27:$O$36,2,0)),VLOOKUP('Data Mahasiswa'!B6:I6,'Data Mahasiswa'!$N$27:$O$36,2,0),0))} -> B- | K6: =IF(AND(E6=2025,I6>=2.75,OR(J6="A",J6="A-",J6="B+",J6="B",J6="B-",J6="C+",J6="C",J6="C-")),"Eligible","Tidak Eligible") -> Eligible
A7: 6 | B7: 25M-A11-0006 | C7: Gema Hidayat | D7: P | E7: =LEFT(B7,2)+2000 -> 2025 | F7: =INDEX('Data Mahasiswa'!$N$1:$Q$14, MATCH(MID('Data Status Pendaftar'!B7, 5,2), 'Data Mahasiswa'!$N$1:$N$14,0),2) -> Sains | G7: {=INDEX('Data Mahasiswa'!$Q$2:$Q$14, MATCH(MID('Data Status Pendaftar'!B7,5,3), 'Data Mahasiswa'!$N$2:$N$14&TEXT('Data Mahasiswa'!$P$2:$P$14,"0"), 0))} -> Matematika | H7: =(YEAR(TODAY())-E7)*2 -> 2 | I7: =INDEX('Data Mahasiswa'!$A$1:$J$701, MATCH('Data Status Pendaftar'!B7, 'Data Mahasiswa'!$A$1:$A$701, 0), 10) -> 2.9479167 | J7: {=INDEX('Data Mahasiswa'!B7:I7,MATCH(MIN(VLOOKUP('Data Mahasiswa'!B7:I7,'Data Mahasiswa'!$N$27:$O$36,2,0)),VLOOKUP('Data Mahasiswa'!B7:I7,'Data Mahasiswa'!$N$27:$O$36,2,0),0))} -> C | K7: =IF(AND(E7=2025,I7>=2.75,OR(J7="A",J7="A-",J7="B+",J7="B",J7="B-",J7="C+",J7="C",J7="C-")),"Eligible","Tidak Eligible") -> Eligible
A8: 7 | B8: 25M-A11-0007 | C8: Citra Wibowo | D8: P | E8: =LEFT(B8,2)+2000 -> 2025 | F8: =INDEX('Data Mahasiswa'!$N$1:$Q$14, MATCH(MID('Data Status Pendaftar'!B8, 5,2), 'Data Mahasiswa'!$N$1:$N$14,0),2) -> Sains | G8: {=INDEX('Data Mahasiswa'!$Q$2:$Q$14, MATCH(MID('Data Status Pendaftar'!B8,5,3), 'Data Mahasiswa'!$N$2:$N$14&TEXT('Data Mahasiswa'!$P$2:$P$14,"0"), 0))} -> Matematika | H8: =(YEAR(TODAY())-E8)*2 -> 2 | I8: =INDEX('Data Mahasiswa'!$A$1:$J$701, MATCH('Data Status Pendaftar'!B8, 'Data Mahasiswa'!$A$1:$A$701, 0), 10) -> 3.0520833 | J8: {=INDEX('Data Mahasiswa'!B8:I8,MATCH(MIN(VLOOKUP('Data Mahasiswa'!B8:I8,'Data Mahasiswa'!$N$27:$O$36,2,0)),VLOOKUP('Data Mahasiswa'!B8:I8,'Data Mahasiswa'!$N$27:$O$36,2,0),0))} -> E | K8: =IF(AND(E8=2025,I8>=2.75,OR(J8="A",J8="A-",J8="B+",J8="B",J8="B-",J8="C+",J8="C",J8="C-")),"Eligible","Tidak Eligible") -> Tidak Eligible
A9: 8 | B9: 25M-A11-0008 | C9: Yuni Siregar | D9: P | E9: =LEFT(B9,2)+2000 -> 2025 | F9: =INDEX('Data Mahasiswa'!$N$1:$Q$14, MATCH(MID('Data Status Pendaftar'!B9, 5,2), 'Data Mahasiswa'!$N$1:$N$14,0),2) -> Sains | G9: {=INDEX('Data Mahasiswa'!$Q$2:$Q$14, MATCH(MID('Data Status Pendaftar'!B9,5,3), 'Data Mahasiswa'!$N$2:$N$14&TEXT('Data Mahasiswa'!$P$2:$P$14,"0"), 0))} -> Matematika | H9: =(YEAR(TODAY())-E9)*2 -> 2 | I9: =INDEX('Data Mahasiswa'!$A$1:$J$701, MATCH('Data Status Pendaftar'!B9, 'Data Mahasiswa'!$A$1:$A$701, 0), 10) -> 3.0104167 | J9: {=INDEX('Data Mahasiswa'!B9:I9,MATCH(MIN(VLOOKUP('Data Mahasiswa'!B9:I9,'Data Mahasiswa'!$N$27:$O$36,2,0)),VLOOKUP('Data Mahasiswa'!B9:I9,'Data Mahasiswa'!$N$27:$O$36,2,0),0))} -> C | K9: =IF(AND(E9=2025,I9>=2.75,OR(J9="A",J9="A-",J9="B+",J9="B",J9="B-",J9="C+",J9="C",J9="C-")),"Eligible","Tidak Eligible") -> Eligible
A10: 9 | B10: 25M-A11-0009 | C10: Gita Maulana | D10: P | E10: =LEFT(B10,2)+2000 -> 2025 | F10: =INDEX('Data Mahasiswa'!$N$1:$Q$14, MATCH(MID('Data Status Pendaftar'!B10, 5,2), 'Data Mahasiswa'!$N$1:$N$14,0),2) -> Sains | G10: {=INDEX('Data Mahasiswa'!$Q$2:$Q$14, MATCH(MID('Data Status Pendaftar'!B10,5,3), 'Data Mahasiswa'!$N$2:$N$14&TEXT('Data Mahasiswa'!$P$2:$P$14,"0"), 0))} -> Matematika | H10: =(YEAR(TODAY())-E10)*2 -> 2 | I10: =INDEX('Data Mahasiswa'!$A$1:$J$701, MATCH('Data Status Pendaftar'!B10, 'Data Mahasiswa'!$A$1:$A$701, 0), 10) -> 2.7708333 | J10: {=INDEX('Data Mahasiswa'!B10:I10,MATCH(MIN(VLOOKUP('Data Mahasiswa'!B10:I10,'Data Mahasiswa'!$N$27:$O$36,2,0)),VLOOKUP('Data Mahasiswa'!B10:I10,'Data Mahasiswa'!$N$27:$O$36,2,0),0))} -> D | K10: =IF(AND(E10=2025,I10>=2.75,OR(J10="A",J10="A-",J10="B+",J10="B",J10="B-",J10="C+",J10="C",J10="C-")),"Eligible","Tidak Eligible") -> Tidak Eligible
A11: 10 | B11: 25M-A11-0010 | C11: Joko Saputra | D11: L | E11: =LEFT(B11,2)+2000 -> 2025 | F11: =INDEX('Data Mahasiswa'!$N$1:$Q$14, MATCH(MID('Data Status Pendaftar'!B11, 5,2), 'Data Mahasiswa'!$N$1:$N$14,0),2) -> Sains | G11: {=INDEX('Data Mahasiswa'!$Q$2:$Q$14, MATCH(MID('Data Status Pendaftar'!B11,5,3), 'Data Mahasiswa'!$N$2:$N$14&TEXT('Data Mahasiswa'!$P$2:$P$14,"0"), 0))} -> Matematika | H11: =(YEAR(TODAY())-E11)*2 -> 2 | I11: =INDEX('Data Mahasiswa'!$A$1:$J$701, MATCH('Data Status Pendaftar'!B11, 'Data Mahasiswa'!$A$1:$A$701, 0), 10) -> 2.65625 | J11: {=INDEX('Data Mahasiswa'!B11:I11,MATCH(MIN(VLOOKUP('Data Mahasiswa'!B11:I11,'Data Mahasiswa'!$N$27:$O$36,2,0)),VLOOKUP('Data Mahasiswa'!B11:I11,'Data Mahasiswa'!$N$27:$O$36,2,0),0))} -> E | K11: =IF(AND(E11=2025,I11>=2.75,OR(J11="A",J11="A-",J11="B+",J11="B",J11="B-",J11="C+",J11="C",J11="C-")),"Eligible","Tidak Eligible") -> Tidak Eligible
A12: 11 | B12: 25M-A11-0011 | C12: Bella Siregar | D12: P | E12: =LEFT(B12,2)+2000 -> 2025 | F12: =INDEX('Data Mahasiswa'!$N$1:$Q$14, MATCH(MID('Data Status Pendaftar'!B12, 5,2), 'Data Mahasiswa'!$N$1:$N$14,0),2) -> Sains | G12: {=INDEX('Data Mahasiswa'!$Q$2:$Q$14, MATCH(MID('Data Status Pendaftar'!B12,5,3), 'Data Mahasiswa'!$N$2:$N$14&TEXT('Data Mahasiswa'!$P$2:$P$14,"0"), 0))} -> Matematika | H12: =(YEAR(TODAY())-E12)*2 -> 2 | I12: =INDEX('Data Mahasiswa'!$A$1:$J$701, MATCH('Data Status Pendaftar'!B12, 'Data Mahasiswa'!$A$1:$A$701, 0), 10) -> 3.3541667 | J12: {=INDEX('Data Mahasiswa'!B12:I12,MATCH(MIN(VLOOKUP('Data Mahasiswa'!B12:I12,'Data Mahasiswa'!$N$27:$O$36,2,0)),VLOOKUP('Data Mahasiswa'!B12:I12,'Data Mahasiswa'!$N$27:$O$36,2,0),0))} -> C | K12: =IF(AND(E12=2025,I12>=2.75,OR(J12="A",J12="A-",J12="B+",J12="B",J12="B-",J12="C+",J12="C",J12="C-")),"Eligible","Tidak Eligible") -> Eligible
A13: 12 | B13: 25M-A11-0012 | C13: Dinda Permana | D13: P | E13: =LEFT(B13,2)+2000 -> 2025 | F13: =INDEX('Data Mahasiswa'!$N$1:$Q$14, MATCH(MID('Data Status Pendaftar'!B13, 5,2), 'Data Mahasiswa'!$N$1:$N$14,0),2) -> Sains | G13: {=INDEX('Data Mahasiswa'!$Q$2:$Q$14, MATCH(MID('Data Status Pendaftar'!B13,5,3), 'Data Mahasiswa'!$N$2:$N$14&TEXT('Data Mahasiswa'!$P$2:$P$14,"0"), 0))} -> Matematika | H13: =(YEAR(TODAY())-E13)*2 -> 2 | I13: =INDEX('Data Mahasiswa'!$A$1:$J$701, MATCH('Data Status Pendaftar'!B13, 'Data Mahasiswa'!$A$1:$A$701, 0), 10) -> 3.1770833 | J13: {=INDEX('Data Mahasiswa'!B13:I13,MATCH(MIN(VLOOKUP('Data Mahasiswa'!B13:I13,'Data Mahasiswa'!$N$27:$O$36,2,0)),VLOOKUP('Data Mahasiswa'!B13:I13,'Data Mahasiswa'!$N$27:$O$36,2,0),0))} -> C | K13: =IF(AND(E13=2025,I13>=2.75,OR(J13="A",J13="A-",J13="B+",J13="B",J13="B-",J13="C+",J13="C",J13="C-")),"Eligible","Tidak Eligible") -> Eligible
... A701: 700 | B701: 25T-A53-0017 | C701: Gilang Oktavianus | D701: L | E701: =LEFT(B701,2)+2000 -> 2025 | F701: =INDEX('Data Mahasiswa'!$N$1:$Q$14, MATCH(MID('Data Status Pendaftar'!B701, 5,2), 'Data Mahasiswa'!$N$1:$N$14,0),2) -> Ilmu Sosial | G701: {=INDEX('Data Mahasiswa'!$Q$2:$Q$14, MATCH(MID('Data Status Pendaftar'!B701,5,3), 'Data Mahasiswa'!$N$2:$N$14&TEXT('Data Mahasiswa'!$P$2:$P$14,"0"), 0))} -> Sosiologi | H701: =(YEAR(TODAY())-E701)*2 -> 2 | I701: =INDEX('Data Mahasiswa'!$A$1:$J$701, MATCH('Data Status Pendaftar'!B701, 'Data Mahasiswa'!$A$1:$A$701, 0), 10) -> 2.9583333 | J701: {=INDEX('Data Mahasiswa'!B701:I701,MATCH(MIN(VLOOKUP('Data Mahasiswa'!B701:I701,'Data Mahasiswa'!$N$27:$O$36,2,0)),VLOOKUP('Data Mahasiswa'!B701:I701,'Data Mahasiswa'!$N$27:$O$36,2,0),0))} -> C | K701: =IF(AND(E701=2025,I701>=2.75,OR(J701="A",J701="A-",J701="B+",J701="B",J701="B-",J701="C+",J701="C",J701="C-")),"Eligible","Tidak Eligible") -> Eligible

Sheet Data Mahasiswa Eligible
A1: Data Mahasiswa Eligible
A2: No | B2: NIM | C2: Nama | D2: Jenis Kelamin | E2: Angkatan | F2: Fakultas | G2: Jurusan | H2: Semester | I2: IPK | J2: Nilai Terendah
A3: {=_xlfn.SEQUENCE(ROWS(_xlfn._xlws.FILTER('Data Status Pendaftar'!A2:A701,'Data Status Pendaftar'!K2:K701="Eligible")))} -> 1 | B3: {=_xlfn._xlws.FILTER(datasts[[NIM]:[Nilai Terendah]],datasts[[Status ]]="Eligible","")} -> 25M-A11-0001 | C3: Zaki Oktavianus | D3: L | E3: 2025 | F3: Sains | G3: Matematika | H3: 2 | I3: 3.4791667 | J3: B-
A4: 2 | B4: 25M-A11-0002 | C4: Rina Kusuma | D4: P | E4: 2025 | F4: Sains | G4: Matematika | H4: 2 | I4: 3.7083333 | J4: C+
A5: 3 | B5: 25M-A11-0004 | C5: Oki Wijaya | D5: L | E5: 2025 | F5: Sains | G5: Matematika | H5: 2 | I5: 3.4270833 | J5: C+
A6: 4 | B6: 25M-A11-0005 | C6: Eka Hidayat | D6: P | E6: 2025 | F6: Sains | G6: Matematika | H6: 2 | I6: 3.4270833 | J6: B-
A7: 5 | B7: 25M-A11-0006 | C7: Gema Hidayat | D7: P | E7: 2025 | F7: Sains | G7: Matematika | H7: 2 | I7: 2.9479167 | J7: C
A8: 6 | B8: 25M-A11-0008 | C8: Yuni Siregar | D8: P | E8: 2025 | F8: Sains | G8: Matematika | H8: 2 | I8: 3.0104167 | J8: C
A9: 7 | B9: 25M-A11-0011 | C9: Bella Siregar | D9: P | E9: 2025 | F9: Sains | G9: Matematika | H9: 2 | I9: 3.3541667 | J9: C
A10: 8 | B10: 25M-A11-0012 | C10: Dinda Permana | D10: P | E10: 2025 | F10: Sains | G10: Matematika | H10: 2 | I10: 3.1770833 | J10: C
A11: 9 | B11: 25M-A11-0015 | C11: Farah Junaedi | D11: P | E11: 2025 | F11: Sains | G11: Matematika | H11: 2 | I11: 2.7708333 | J11: C
A12: 10 | B12: 25M-A11-0016 | C12: Ira Suryadi | D12: P | E12: 2025 | F12: Sains | G12: Matematika | H12: 2 | I12: 3.6041667 | J12: B-
A13: 11 | B13: 25M-A12-0001 | C13: Fitri Prasetyo | D13: P | E13: 2025 | F13: Sains | G13: Statistika | H13: 2 | I13: 3.5104167 | J13: C
A14: 12 | B14: 25M-A12-0003 | C14: Yuni Nasution | D14: P | E14: 2025 | F14: Sains | G14: Statistika | H14: 2 | I14: 3.375 | J14: C+
A15: 13 | B15: 25M-A12-0005 | C15: Siti Zulkarnain | D15: P | E15: 2025 | F15: Sains | G15: Statistika | H15: 2 | I15: 2.8541667 | J15: C
... A375: 373 | B375: 25T-A53-0017 | C375: Gilang Oktavianus | D375: L | E375: 2025 | F375: Ilmu Sosial | G375: Sosiologi | H375: 2 | I375: 2.9583333 | J375: C

Sheet Data Mahasiswa
A1: NIM | B1: Mata Kuliah 1 (4 sks) | C1: Mata kuliah 2 (4 sks) | D1: Mata kuliah 3 (2 sks) | E1: Mata kuliah 4 (3 sks) | F1: Mata kuliah 5 (2 sks) | G1: Mata kuliah 6 (2 sks) | H1: Mata kuliah 7 (3 sks) | I1: Mata kuliah 8 ( 4 sks) | J1: IPK | N1: Kode | O1: Fakultas | P1: Kode Jurusan | Q1: Jurusan
A2: 25M-A11-0001 | B2: B+ | C2: A- | D2: B- | E2: A | F2: B | G2: B+ | H2: A | I2: B | J2: =(VLOOKUP(B2,$N$27:$O$36, 2,0)*4+VLOOKUP(C2,$N$27:$O$36, 2,0)*4+VLOOKUP(D2,$N$27:$O$36, 2,0)*2+VLOOKUP(E2,$N$27:$O$36, 2,0)*3+VLOOKUP(F2,$N$27:$O$36, 2,0)*2+VLOOKUP(G2,$N$27:$O$36, 2,0)*2+VLOOKUP(H2,$N$27:$O$36, 2,0)*3+VLOOKUP(I2,$N$27:$O$36, 2,0)*4)/24 -> 3.4791667 | N2: A1 | O2: Sains | P2: 1 | Q2: Matematika
A3: 25M-A11-0002 | B3: A | C3: B+ | D3: A | E3: A | F3: B+ | G3: C+ | H3: A | I3: A- | J3: =(VLOOKUP(B3,$N$27:$O$36, 2,0)*4+VLOOKUP(C3,$N$27:$O$36, 2,0)*4+VLOOKUP(D3,$N$27:$O$36, 2,0)*2+VLOOKUP(E3,$N$27:$O$36, 2,0)*3+VLOOKUP(F3,$N$27:$O$36, 2,0)*2+VLOOKUP(G3,$N$27:$O$36, 2,0)*2+VLOOKUP(H3,$N$27:$O$36, 2,0)*3+VLOOKUP(I3,$N$27:$O$36, 2,0)*4)/24 -> 3.7083333 | N3: A1 | O3: Sains | P3: 2 | Q3: Statistika
A4: 25M-A11-0003 | B4: B | C4: D | D4: B | E4: B+ | F4: E | G4: A | H4: C | I4: A- | J4: =(VLOOKUP(B4,$N$27:$O$36, 2,0)*4+VLOOKUP(C4,$N$27:$O$36, 2,0)*4+VLOOKUP(D4,$N$27:$O$36, 2,0)*2+VLOOKUP(E4,$N$27:$O$36, 2,0)*3+VLOOKUP(F4,$N$27:$O$36, 2,0)*2+VLOOKUP(G4,$N$27:$O$36, 2,0)*2+VLOOKUP(H4,$N$27:$O$36, 2,0)*3+VLOOKUP(I4,$N$27:$O$36, 2,0)*4)/24 -> 2.5625 | N4: A1 | O4: Sains | P4: 3 | Q4: Biologi
A5: 25M-A11-0004 | B5: A | C5: A | D5: B+ | E5: C+ | F5: A- | G5: B | H5: B- | I5: B+ | J5: =(VLOOKUP(B5,$N$27:$O$36, 2,0)*4+VLOOKUP(C5,$N$27:$O$36, 2,0)*4+VLOOKUP(D5,$N$27:$O$36, 2,0)*2+VLOOKUP(E5,$N$27:$O$36, 2,0)*3+VLOOKUP(F5,$N$27:$O$36, 2,0)*2+VLOOKUP(G5,$N$27:$O$36, 2,0)*2+VLOOKUP(H5,$N$27:$O$36, 2,0)*3+VLOOKUP(I5,$N$27:$O$36, 2,0)*4)/24 -> 3.4270833 | N5: A2 | O5: Teknik | P5: 1 | Q5: Teknik Informatika
A6: 25M-A11-0005 | B6: B | C6: A | D6: A | E6: A- | F6: B- | G6: B+ | H6: B+ | I6: B | J6: =(VLOOKUP(B6,$N$27:$O$36, 2,0)*4+VLOOKUP(C6,$N$27:$O$36, 2,0)*4+VLOOKUP(D6,$N$27:$O$36, 2,0)*2+VLOOKUP(E6,$N$27:$O$36, 2,0)*3+VLOOKUP(F6,$N$27:$O$36, 2,0)*2+VLOOKUP(G6,$N$27:$O$36, 2,0)*2+VLOOKUP(H6,$N$27:$O$36, 2,0)*3+VLOOKUP(I6,$N$27:$O$36, 2,0)*4)/24 -> 3.4270833 | N6: A2 | O6: Teknik | P6: 2 | Q6: Teknik Industri
A7: 25M-A11-0006 | B7: B | C7: A- | D7: C+ | E7: B- | F7: A- | G7: B | H7: B | I7: C | J7: =(VLOOKUP(B7,$N$27:$O$36, 2,0)*4+VLOOKUP(C7,$N$27:$O$36, 2,0)*4+VLOOKUP(D7,$N$27:$O$36, 2,0)*2+VLOOKUP(E7,$N$27:$O$36, 2,0)*3+VLOOKUP(F7,$N$27:$O$36, 2,0)*2+VLOOKUP(G7,$N$27:$O$36, 2,0)*2+VLOOKUP(H7,$N$27:$O$36, 2,0)*3+VLOOKUP(I7,$N$27:$O$36, 2,0)*4)/24 -> 2.9479167 | N7: A3 | O7: Ekonomi | P7: 1 | Q7: Manajemen
A8: 25M-A11-0007 | B8: B- | C8: A- | D8: E | E8: A | F8: B+ | G8: C+ | H8: A- | I8: B | J8: =(VLOOKUP(B8,$N$27:$O$36, 2,0)*4+VLOOKUP(C8,$N$27:$O$36, 2,0)*4+VLOOKUP(D8,$N$27:$O$36, 2,0)*2+VLOOKUP(E8,$N$27:$O$36, 2,0)*3+VLOOKUP(F8,$N$27:$O$36, 2,0)*2+VLOOKUP(G8,$N$27:$O$36, 2,0)*2+VLOOKUP(H8,$N$27:$O$36, 2,0)*3+VLOOKUP(I8,$N$27:$O$36, 2,0)*4)/24 -> 3.0520833 | N8: A3 | O8: Ekonomi | P8: 2 | Q8: Akuntansi
A9: 25M-A11-0008 | B9: A | C9: B- | D9: C+ | E9: B | F9: C | G9: B+ | H9: B- | I9: B | J9: =(VLOOKUP(B9,$N$27:$O$36, 2,0)*4+VLOOKUP(C9,$N$27:$O$36, 2,0)*4+VLOOKUP(D9,$N$27:$O$36, 2,0)*2+VLOOKUP(E9,$N$27:$O$36, 2,0)*3+VLOOKUP(F9,$N$27:$O$36, 2,0)*2+VLOOKUP(G9,$N$27:$O$36, 2,0)*2+VLOOKUP(H9,$N$27:$O$36, 2,0)*3+VLOOKUP(I9,$N$27:$O$36, 2,0)*4)/24 -> 3.0104167 | N9: A3 | O9: Ekonomi | P9: 3 | Q9: Ekonomi Pembangunan
A10: 25M-A11-0009 | B10: B | C10: B | D10: C+ | E10: D | F10: B | G10: B- | H10: A | I10: B- | J10: =(VLOOKUP(B10,$N$27:$O$36, 2,0)*4+VLOOKUP(C10,$N$27:$O$36, 2,0)*4+VLOOKUP(D10,$N$27:$O$36, 2,0)*2+VLOOKUP(E10,$N$27:$O$36, 2,0)*3+VLOOKUP(F10,$N$27:$O$36, 2,0)*2+VLOOKUP(G10,$N$27:$O$36, 2,0)*2+VLOOKUP(H10,$N$27:$O$36, 2,0)*3+VLOOKUP(I10,$N$27:$O$36, 2,0)*4)/24 -> 2.7708333 | N10: A4 | O10: Pertanian | P10: 1 | Q10: Agroteknologi
A11: 25M-A11-0010 | B11: B- | C11: E | D11: C+ | E11: A- | F11: B+ | G11: B- | H11: A | I11: B | J11: =(VLOOKUP(B11,$N$27:$O$36, 2,0)*4+VLOOKUP(C11,$N$27:$O$36, 2,0)*4+VLOOKUP(D11,$N$27:$O$36, 2,0)*2+VLOOKUP(E11,$N$27:$O$36, 2,0)*3+VLOOKUP(F11,$N$27:$O$36, 2,0)*2+VLOOKUP(G11,$N$27:$O$36, 2,0)*2+VLOOKUP(H11,$N$27:$O$36, 2,0)*3+VLOOKUP(I11,$N$27:$O$36, 2,0)*4)/24 -> 2.65625 | N11: A4 | O11: Pertanian | P11: 2 | Q11: Agribisnis
A12: 25M-A11-0011 | B12: A- | C12: A | D12: A | E12: C+ | F12: A | G12: A- | H12: B+ | I12: C | J12: =(VLOOKUP(B12,$N$27:$O$36, 2,0)*4+VLOOKUP(C12,$N$27:$O$36, 2,0)*4+VLOOKUP(D12,$N$27:$O$36, 2,0)*2+VLOOKUP(E12,$N$27:$O$36, 2,0)*3+VLOOKUP(F12,$N$27:$O$36, 2,0)*2+VLOOKUP(G12,$N$27:$O$36, 2,0)*2+VLOOKUP(H12,$N$27:$O$36, 2,0)*3+VLOOKUP(I12,$N$27:$O$36, 2,0)*4)/24 -> 3.3541667 | N12: A5 | O12: Ilmu Sosial | P12: 1 | Q12: Administrasi Publik
A13: 25M-A11-0012 | B13: A | C13: B+ | D13: B | E13: C | F13: C+ | G13: C | H13: A- | I13: B+ | J13: =(VLOOKUP(B13,$N$27:$O$36, 2,0)*4+VLOOKUP(C13,$N$27:$O$36, 2,0)*4+VLOOKUP(D13,$N$27:$O$36, 2,0)*2+VLOOKUP(E13,$N$27:$O$36, 2,0)*3+VLOOKUP(F13,$N$27:$O$36, 2,0)*2+VLOOKUP(G13,$N$27:$O$36, 2,0)*2+VLOOKUP(H13,$N$27:$O$36, 2,0)*3+VLOOKUP(I13,$N$27:$O$36, 2,0)*4)/24 -> 3.1770833 | N13: A5 | O13: Ilmu Sosial | P13: 2 | Q13: Ilmu Komunikasi
A14: 25M-A11-0013 | B14: B+ | C14: C | D14: D | E14: A- | F14: A- | G14: A- | H14: A- | I14: B | J14: =(VLOOKUP(B14,$N$27:$O$36, 2,0)*4+VLOOKUP(C14,$N$27:$O$36, 2,0)*4+VLOOKUP(D14,$N$27:$O$36, 2,0)*2+VLOOKUP(E14,$N$27:$O$36, 2,0)*3+VLOOKUP(F14,$N$27:$O$36, 2,0)*2+VLOOKUP(G14,$N$27:$O$36, 2,0)*2+VLOOKUP(H14,$N$27:$O$36, 2,0)*3+VLOOKUP(I14,$N$27:$O$36, 2,0)*4)/24 -> 3.0625 | N14: A5 | O14: Ilmu Sosial | P14: 3 | Q14: Sosiologi
A15: 25M-A11-0014 | B15: B | C15: A- | D15: A | E15: B+ | F15: B+ | G15: B | H15: D | I15: B- | J15: =(VLOOKUP(B15,$N$27:$O$36, 2,0)*4+VLOOKUP(C15,$N$27:$O$36, 2,0)*4+VLOOKUP(D15,$N$27:$O$36, 2,0)*2+VLOOKUP(E15,$N$27:$O$36, 2,0)*3+VLOOKUP(F15,$N$27:$O$36, 2,0)*2+VLOOKUP(G15,$N$27:$O$36, 2,0)*2+VLOOKUP(H15,$N$27:$O$36, 2,0)*3+VLOOKUP(I15,$N$27:$O$36, 2,0)*4)/24 -> 3.0208333
A16: 25M-A11-0015 | B16: B | C16: B | D16: B- | E16: A | F16: C | G16: C+ | H16: C | I16: C+ | J16: =(VLOOKUP(B16,$N$27:$O$36, 2,0)*4+VLOOKUP(C16,$N$27:$O$36, 2,0)*4+VLOOKUP(D16,$N$27:$O$36, 2,0)*2+VLOOKUP(E16,$N$27:$O$36, 2,0)*3+VLOOKUP(F16,$N$27:$O$36, 2,0)*2+VLOOKUP(G16,$N$27:$O$36, 2,0)*2+VLOOKUP(H16,$N$27:$O$36, 2,0)*3+VLOOKUP(I16,$N$27:$O$36, 2,0)*4)/24 -> 2.7708333
A17: 25M-A11-0016 | B17: B+ | C17: B+ | D17: A | E17: B- | F17: A | G17: A | H17: A- | I17: A- | J17: =(VLOOKUP(B17,$N$27:$O$36, 2,0)*4+VLOOKUP(C17,$N$27:$O$36, 2,0)*4+VLOOKUP(D17,$N$27:$O$36, 2,0)*2+VLOOKUP(E17,$N$27:$O$36, 2,0)*3+VLOOKUP(F17,$N$27:$O$36, 2,0)*2+VLOOKUP(G17,$N$27:$O$36, 2,0)*2+VLOOKUP(H17,$N$27:$O$36, 2,0)*3+VLOOKUP(I17,$N$27:$O$36, 2,0)*4)/24 -> 3.6041667 | N17: Jalur Masuk | O17: Kode
A18: 25M-A12-0001 | B18: B+ | C18: A | D18: A | E18: A- | F18: A | G18: B+ | H18: A | I18: C | J18: =(VLOOKUP(B18,$N$27:$O$36, 2,0)*4+VLOOKUP(C18,$N$27:$O$36, 2,0)*4+VLOOKUP(D18,$N$27:$O$36, 2,0)*2+VLOOKUP(E18,$N$27:$O$36, 2,0)*3+VLOOKUP(F18,$N$27:$O$36, 2,0)*2+VLOOKUP(G18,$N$27:$O$36, 2,0)*2+VLOOKUP(H18,$N$27:$O$36, 2,0)*3+VLOOKUP(I18,$N$27:$O$36, 2,0)*4)/24 -> 3.5104167 | N18: Tes | O18: T
A19: 25M-A12-0002 | B19: B | C19: A | D19: A- | E19: B+ | F19: B+ | G19: A | H19: C+ | I19: E | J19: =(VLOOKUP(B19,$N$27:$O$36, 2,0)*4+VLOOKUP(C19,$N$27:$O$36, 2,0)*4+VLOOKUP(D19,$N$27:$O$36, 2,0)*2+VLOOKUP(E19,$N$27:$O$36, 2,0)*3+VLOOKUP(F19,$N$27:$O$36, 2,0)*2+VLOOKUP(G19,$N$27:$O$36, 2,0)*2+VLOOKUP(H19,$N$27:$O$36, 2,0)*3+VLOOKUP(I19,$N$27:$O$36, 2,0)*4)/24 -> 2.8541667 | N19: Raport | O19: R
A20: 25M-A12-0003 | B20: B | C20: B | D20: A | E20: A | F20: B+ | G20: A- | H20: C+ | I20: A- | J20: =(VLOOKUP(B20,$N$27:$O$36, 2,0)*4+VLOOKUP(C20,$N$27:$O$36, 2,0)*4+VLOOKUP(D20,$N$27:$O$36, 2,0)*2+VLOOKUP(E20,$N$27:$O$36, 2,0)*3+VLOOKUP(F20,$N$27:$O$36, 2,0)*2+VLOOKUP(G20,$N$27:$O$36, 2,0)*2+VLOOKUP(H20,$N$27:$O$36, 2,0)*3+VLOOKUP(I20,$N$27:$O$36, 2,0)*4)/24 -> 3.375 | N20: Mandiri | O20: M
A21: 25M-A12-0004 | B21: A | C21: D | D21: B | E21: A | F21: B | G21: A | H21: B | I21: E | J21: =(VLOOKUP(B21,$N$27:$O$36, 2,0)*4+VLOOKUP(C21,$N$27:$O$36, 2,0)*4+VLOOKUP(D21,$N$27:$O$36, 2,0)*2+VLOOKUP(E21,$N$27:$O$36, 2,0)*3+VLOOKUP(F21,$N$27:$O$36, 2,0)*2+VLOOKUP(G21,$N$27:$O$36, 2,0)*2+VLOOKUP(H21,$N$27:$O$36, 2,0)*3+VLOOKUP(I21,$N$27:$O$36, 2,0)*4)/24 -> 2.5416667
A22: 25M-A12-0005 | B22: C | C22: B- | D22: A- | E22: B+ | F22: A- | G22: C+ | H22: B | I22: C+ | J22: =(VLOOKUP(B22,$N$27:$O$36, 2,0)*4+VLOOKUP(C22,$N$27:$O$36, 2,0)*4+VLOOKUP(D22,$N$27:$O$36, 2,0)*2+VLOOKUP(E22,$N$27:$O$36, 2,0)*3+VLOOKUP(F22,$N$27:$O$36, 2,0)*2+VLOOKUP(G22,$N$27:$O$36, 2,0)*2+VLOOKUP(H22,$N$27:$O$36, 2,0)*3+VLOOKUP(I22,$N$27:$O$36, 2,0)*4)/24 -> 2.8541667
A23: 25M-A12-0006 | B23: B+ | C23: A- | D23: C+ | E23: E | F23: C | G23: C+ | H23: C+ | I23: B- | J23: =(VLOOKUP(B23,$N$27:$O$36, 2,0)*4+VLOOKUP(C23,$N$27:$O$36, 2,0)*4+VLOOKUP(D23,$N$27:$O$36, 2,0)*2+VLOOKUP(E23,$N$27:$O$36, 2,0)*3+VLOOKUP(F23,$N$27:$O$36, 2,0)*2+VLOOKUP(G23,$N$27:$O$36, 2,0)*2+VLOOKUP(H23,$N$27:$O$36, 2,0)*3+VLOOKUP(I23,$N$27:$O$36, 2,0)*4)/24 -> 2.5625
A24: 25M-A12-0007 | B24: A- | C24: B | D24: B+ | E24: A | F24: A | G24: A- | H24: A- | I24: B- | J24: =(VLOOKUP(B24,$N$27:$O$36, 2,0)*4+VLOOKUP(C24,$N$27:$O$36, 2,0)*4+VLOOKUP(D24,$N$27:$O$36, 2,0)*2+VLOOKUP(E24,$N$27:$O$36, 2,0)*3+VLOOKUP(F24,$N$27:$O$36, 2,0)*2+VLOOKUP(G24,$N$27:$O$36, 2,0)*2+VLOOKUP(H24,$N$27:$O$36, 2,0)*3+VLOOKUP(I24,$N$27:$O$36, 2,0)*4)/24 -> 3.4895833
A25: 25M-A12-0008 | B25: D | C25: B+ | D25: D | E25: E | F25: D | G25: B+ | H25: A- | I25: A- | J25: =(VLOOKUP(B25,$N$27:$O$36, 2,0)*4+VLOOKUP(C25,$N$27:$O$36, 2,0)*4+VLOOKUP(D25,$N$27:$O$36, 2,0)*2+VLOOKUP(E25,$N$27:$O$36, 2,0)*3+VLOOKUP(F25,$N$27:$O$36, 2,0)*2+VLOOKUP(G25,$N$27:$O$36, 2,0)*2+VLOOKUP(H25,$N$27:$O$36, 2,0)*3+VLOOKUP(I25,$N$27:$O$36, 2,0)*4)/24 -> 2.3020833
A26: 25M-A12-0009 | B26: A- | C26: A- | D26: B | E26: C | F26: C+ | G26: B | H26: B- | I26: C+ | J26: =(VLOOKUP(B26,$N$27:$O$36, 2,0)*4+VLOOKUP(C26,$N$27:$O$36, 2,0)*4+VLOOKUP(D26,$N$27:$O$36, 2,0)*2+VLOOKUP(E26,$N$27:$O$36, 2,0)*3+VLOOKUP(F26,$N$27:$O$36, 2,0)*2+VLOOKUP(G26,$N$27:$O$36, 2,0)*2+VLOOKUP(H26,$N$27:$O$36, 2,0)*3+VLOOKUP(I26,$N$27:$O$36, 2,0)*4)/24 -> 2.96875
A27: 25M-A12-0010 | B27: A | C27: B- | D27: C | E27: C+ | F27: C+ | G27: B | H27: A- | I27: C+ | J27: =(VLOOKUP(B27,$N$27:$O$36, 2,0)*4+VLOOKUP(C27,$N$27:$O$36, 2,0)*4+VLOOKUP(D27,$N$27:$O$36, 2,0)*2+VLOOKUP(E27,$N$27:$O$36, 2,0)*3+VLOOKUP(F27,$N$27:$O$36, 2,0)*2+VLOOKUP(G27,$N$27:$O$36, 2,0)*2+VLOOKUP(H27,$N$27:$O$36, 2,0)*3+VLOOKUP(I27,$N$27:$O$36, 2,0)*4)/24 -> 2.9479167 | N27: Nilai | O27: Bobot
A28: 25M-A12-0011 | B28: B+ | C28: C+ | D28: E | E28: B+ | F28: B+ | G28: D | H28: B- | I28: A- | J28: =(VLOOKUP(B28,$N$27:$O$36, 2,0)*4+VLOOKUP(C28,$N$27:$O$36, 2,0)*4+VLOOKUP(D28,$N$27:$O$36, 2,0)*2+VLOOKUP(E28,$N$27:$O$36, 2,0)*3+VLOOKUP(F28,$N$27:$O$36, 2,0)*2+VLOOKUP(G28,$N$27:$O$36, 2,0)*2+VLOOKUP(H28,$N$27:$O$36, 2,0)*3+VLOOKUP(I28,$N$27:$O$36, 2,0)*4)/24 -> 2.78125 | N28: A | O28: 4
A29: 25M-A12-0012 | B29: A | C29: A- | D29: C | E29: C+ | F29: A | G29: C+ | H29: E | I29: B- | J29: =(VLOOKUP(B29,$N$27:$O$36, 2,0)*4+VLOOKUP(C29,$N$27:$O$36, 2,0)*4+VLOOKUP(D29,$N$27:$O$36, 2,0)*2+VLOOKUP(E29,$N$27:$O$36, 2,0)*3+VLOOKUP(F29,$N$27:$O$36, 2,0)*2+VLOOKUP(G29,$N$27:$O$36, 2,0)*2+VLOOKUP(H29,$N$27:$O$36, 2,0)*3+VLOOKUP(I29,$N$27:$O$36, 2,0)*4)/24 -> 2.7708333 | N29: A- | O29: 3.75
A30: 25M-A12-0013 | B30: B+ | C30: B | D30: A | E30: A | F30: E | G30: B- | H30: B | I30: D | J30: =(VLOOKUP(B30,$N$27:$O$36, 2,0)*4+VLOOKUP(C30,$N$27:$O$36, 2,0)*4+VLOOKUP(D30,$N$27:$O$36, 2,0)*2+VLOOKUP(E30,$N$27:$O$36, 2,0)*3+VLOOKUP(F30,$N$27:$O$36, 2,0)*2+VLOOKUP(G30,$N$27:$O$36, 2,0)*2+VLOOKUP(H30,$N$27:$O$36, 2,0)*3+VLOOKUP(I30,$N$27:$O$36, 2,0)*4)/24 -> 2.6875 | N30: B+ | O30: 3.5
A31: 25M-A12-0014 | B31: B+ | C31: C | D31: C+ | E31: A- | F31: A- | G31: A- | H31: A- | I31: B | J31: =(VLOOKUP(B31,$N$27:$O$36, 2,0)*4+VLOOKUP(C31,$N$27:$O$36, 2,0)*4+VLOOKUP(D31,$N$27:$O$36, 2,0)*2+VLOOKUP(E31,$N$27:$O$36, 2,0)*3+VLOOKUP(F31,$N$27:$O$36, 2,0)*2+VLOOKUP(G31,$N$27:$O$36, 2,0)*2+VLOOKUP(H31,$N$27:$O$36, 2,0)*3+VLOOKUP(I31,$N$27:$O$36, 2,0)*4)/24 -> 3.1875 | N31: B | O31: 3
A32: 25M-A12-0015 | B32: A- | C32: B+ | D32: A | E32: C | F32: B+ | G32: B | H32: B | I32: C | J32: =(VLOOKUP(B32,$N$27:$O$36, 2,0)*4+VLOOKUP(C32,$N$27:$O$36, 2,0)*4+VLOOKUP(D32,$N$27:$O$36, 2,0)*2+VLOOKUP(E32,$N$27:$O$36, 2,0)*3+VLOOKUP(F32,$N$27:$O$36, 2,0)*2+VLOOKUP(G32,$N$27:$O$36, 2,0)*2+VLOOKUP(H32,$N$27:$O$36, 2,0)*3+VLOOKUP(I32,$N$27:$O$36, 2,0)*4)/24 -> 3.0416667 | N32: B- | O32: 2.75
A33: 25M-A12-0016 | B33: B+ | C33: C | D33: B | E33: B | F33: B | G33: A | H33: B+ | I33: A- | J33: =(VLOOKUP(B33,$N$27:$O$36, 2,0)*4+VLOOKUP(C33,$N$27:$O$36, 2,0)*4+VLOOKUP(D33,$N$27:$O$36, 2,0)*2+VLOOKUP(E33,$N$27:$O$36, 2,0)*3+VLOOKUP(F33,$N$27:$O$36, 2,0)*2+VLOOKUP(G33,$N$27:$O$36, 2,0)*2+VLOOKUP(H33,$N$27:$O$36, 2,0)*3+VLOOKUP(I33,$N$27:$O$36, 2,0)*4)/24 -> 3.1875 | N33: C+ | O33: 2.5
A34: 25M-A12-0017 | B34: A | C34: C+ | D34: A- | E34: B | F34: B- | G34: B | H34: B+ | I34: B | J34: =(VLOOKUP(B34,$N$27:$O$36, 2,0)*4+VLOOKUP(C34,$N$27:$O$36, 2,0)*4+VLOOKUP(D34,$N$27:$O$36, 2,0)*2+VLOOKUP(E34,$N$27:$O$36, 2,0)*3+VLOOKUP(F34,$N$27:$O$36, 2,0)*2+VLOOKUP(G34,$N$27:$O$36, 2,0)*2+VLOOKUP(H34,$N$27:$O$36, 2,0)*3+VLOOKUP(I34,$N$27:$O$36, 2,0)*4)/24 -> 3.1875 | N34: C | O34: 2
A35: 25M-A12-0018 | B35: B | C35: C+ | D35: A | E35: B | F35: A- | G35: A- | H35: C+ | I35: B | J35: =(VLOOKUP(B35,$N$27:$O$36, 2,0)*4+VLOOKUP(C35,$N$27:$O$36, 2,0)*4+VLOOKUP(D35,$N$27:$O$36, 2,0)*2+VLOOKUP(E35,$N$27:$O$36, 2,0)*3+VLOOKUP(F35,$N$27:$O$36, 2,0)*2+VLOOKUP(G35,$N$27:$O$36, 2,0)*2+VLOOKUP(H35,$N$27:$O$36, 2,0)*3+VLOOKUP(I35,$N$27:$O$36, 2,0)*4)/24 -> 3.0625 | N35: D | O35: 1
A36: 25M-A12-0019 | B36: B | C36: C+ | D36: C | E36: B+ | F36: B | G36: B | H36: B | I36: B- | J36: =(VLOOKUP(B36,$N$27:$O$36, 2,0)*4+VLOOKUP(C36,$N$27:$O$36, 2,0)*4+VLOOKUP(D36,$N$27:$O$36, 2,0)*2+VLOOKUP(E36,$N$27:$O$36, 2,0)*3+VLOOKUP(F36,$N$27:$O$36, 2,0)*2+VLOOKUP(G36,$N$27:$O$36, 2,0)*2+VLOOKUP(H36,$N$27:$O$36, 2,0)*3+VLOOKUP(I36,$N$27:$O$36, 2,0)*4)/24 -> 2.8541667 | N36: E | O36: 0
A37: 25M-A12-0020 | B37: B | C37: B | D37: B | E37: D | F37: B- | G37: C | H37: D | I37: A- | J37: =(VLOOKUP(B37,$N$27:$O$36, 2,0)*4+VLOOKUP(C37,$N$27:$O$36, 2,0)*4+VLOOKUP(D37,$N$27:$O$36, 2,0)*2+VLOOKUP(E37,$N$27:$O$36, 2,0)*3+VLOOKUP(F37,$N$27:$O$36, 2,0)*2+VLOOKUP(G37,$N$27:$O$36, 2,0)*2+VLOOKUP(H37,$N$27:$O$36, 2,0)*3+VLOOKUP(I37,$N$27:$O$36, 2,0)*4)/24 -> 2.5208333
A38: 25M-A12-0021 | B38: B | C38: D | D38: C+ | E38: A | F38: A | G38: B+ | H38: A | I38: A- | J38: =(VLOOKUP(B38,$N$27:$O$36, 2,0)*4+VLOOKUP(C38,$N$27:$O$36, 2,0)*4+VLOOKUP(D38,$N$27:$O$36, 2,0)*2+VLOOKUP(E38,$N$27:$O$36, 2,0)*3+VLOOKUP(F38,$N$27:$O$36, 2,0)*2+VLOOKUP(G38,$N$27:$O$36, 2,0)*2+VLOOKUP(H38,$N$27:$O$36, 2,0)*3+VLOOKUP(I38,$N$27:$O$36, 2,0)*4)/24 -> 3.125
A39: 25M-A12-0022 | B39: A | C39: B- | D39: C+ | E39: C | F39: A- | G39: B- | H39: B- | I39: A | J39: =(VLOOKUP(B39,$N$27:$O$36, 2,0)*4+VLOOKUP(C39,$N$27:$O$36, 2,0)*4+VLOOKUP(D39,$N$27:$O$36, 2,0)*2+VLOOKUP(E39,$N$27:$O$36, 2,0)*3+VLOOKUP(F39,$N$27:$O$36, 2,0)*2+VLOOKUP(G39,$N$27:$O$36, 2,0)*2+VLOOKUP(H39,$N$27:$O$36, 2,0)*3+VLOOKUP(I39,$N$27:$O$36, 2,0)*4)/24 -> 3.1354167
A40: 25M-A12-0023 | B40: C | C40: D | D40: A- | E40: D | F40: B+ | G40: B | H40: E | I40: C+ | J40: =(VLOOKUP(B40,$N$27:$O$36, 2,0)*4+VLOOKUP(C40,$N$27:$O$36, 2,0)*4+VLOOKUP(D40,$N$27:$O$36, 2,0)*2+VLOOKUP(E40,$N$27:$O$36, 2,0)*3+VLOOKUP(F40,$N$27:$O$36, 2,0)*2+VLOOKUP(G40,$N$27:$O$36, 2,0)*2+VLOOKUP(H40,$N$27:$O$36, 2,0)*3+VLOOKUP(I40,$N$27:$O$36, 2,0)*4)/24 -> 1.8958333
...
